{
 "cells": [
  {
   "cell_type": "code",
   "execution_count": 4,
   "metadata": {
    "collapsed": true
   },
   "outputs": [],
   "source": [
    "import pandas as pd\n",
    "from keras.models import Sequential\n",
    "from keras.layers import Dense\n"
   ]
  },
  {
   "cell_type": "code",
   "execution_count": 26,
   "metadata": {},
   "outputs": [],
   "source": [
    "base = pd.read_csv('iris.csv')\n",
    "base.head()\n",
    "\n",
    "base = pd.read_csv('iris.csv')\n",
    "previsores = base.iloc[:, 0:4].values\n",
    "classe = base.iloc[:, 4].values"
   ]
  },
  {
   "cell_type": "code",
   "execution_count": 27,
   "metadata": {
    "collapsed": true
   },
   "outputs": [],
   "source": [
    "from sklearn.model_selection import train_test_split"
   ]
  },
  {
   "cell_type": "code",
   "execution_count": 31,
   "metadata": {},
   "outputs": [],
   "source": [
    "previsores_treinamento, previsores_teste, classe_treinamento, classe_teste = train_test_split(previsores, classes, test_size=0.25)"
   ]
  },
  {
   "cell_type": "code",
   "execution_count": 32,
   "metadata": {},
   "outputs": [
    {
     "ename": "ValueError",
     "evalue": "Error when checking target: expected dense_42 to have shape (None, 3) but got array with shape (112, 1)",
     "output_type": "error",
     "traceback": [
      "\u001b[0;31m---------------------------------------------------------------------------\u001b[0m",
      "\u001b[0;31mValueError\u001b[0m                                Traceback (most recent call last)",
      "\u001b[0;32m<ipython-input-32-d877918cb125>\u001b[0m in \u001b[0;36m<module>\u001b[0;34m()\u001b[0m\n\u001b[1;32m      5\u001b[0m classificador.compile(optimizer = 'adam', loss = 'categorical_crossentropy',\n\u001b[1;32m      6\u001b[0m                       metrics = ['categorical_accuracy'])\n\u001b[0;32m----> 7\u001b[0;31m \u001b[0mclassificador\u001b[0m\u001b[0;34m.\u001b[0m\u001b[0mfit\u001b[0m\u001b[0;34m(\u001b[0m\u001b[0mprevisores_treinamento\u001b[0m\u001b[0;34m,\u001b[0m \u001b[0mclasse_treinamento\u001b[0m\u001b[0;34m,\u001b[0m \u001b[0mbatch_size\u001b[0m \u001b[0;34m=\u001b[0m \u001b[0;36m10\u001b[0m\u001b[0;34m,\u001b[0m\u001b[0mepochs\u001b[0m \u001b[0;34m=\u001b[0m \u001b[0;36m1000\u001b[0m\u001b[0;34m)\u001b[0m\u001b[0;34m\u001b[0m\u001b[0m\n\u001b[0m",
      "\u001b[0;32m~/anaconda3/envs/myDjangoEnv/lib/python3.6/site-packages/keras/models.py\u001b[0m in \u001b[0;36mfit\u001b[0;34m(self, x, y, batch_size, epochs, verbose, callbacks, validation_split, validation_data, shuffle, class_weight, sample_weight, initial_epoch, **kwargs)\u001b[0m\n\u001b[1;32m    868\u001b[0m                               \u001b[0mclass_weight\u001b[0m\u001b[0;34m=\u001b[0m\u001b[0mclass_weight\u001b[0m\u001b[0;34m,\u001b[0m\u001b[0;34m\u001b[0m\u001b[0m\n\u001b[1;32m    869\u001b[0m                               \u001b[0msample_weight\u001b[0m\u001b[0;34m=\u001b[0m\u001b[0msample_weight\u001b[0m\u001b[0;34m,\u001b[0m\u001b[0;34m\u001b[0m\u001b[0m\n\u001b[0;32m--> 870\u001b[0;31m                               initial_epoch=initial_epoch)\n\u001b[0m\u001b[1;32m    871\u001b[0m \u001b[0;34m\u001b[0m\u001b[0m\n\u001b[1;32m    872\u001b[0m     def evaluate(self, x, y, batch_size=32, verbose=1,\n",
      "\u001b[0;32m~/anaconda3/envs/myDjangoEnv/lib/python3.6/site-packages/keras/engine/training.py\u001b[0m in \u001b[0;36mfit\u001b[0;34m(self, x, y, batch_size, epochs, verbose, callbacks, validation_split, validation_data, shuffle, class_weight, sample_weight, initial_epoch, **kwargs)\u001b[0m\n\u001b[1;32m   1433\u001b[0m             \u001b[0mclass_weight\u001b[0m\u001b[0;34m=\u001b[0m\u001b[0mclass_weight\u001b[0m\u001b[0;34m,\u001b[0m\u001b[0;34m\u001b[0m\u001b[0m\n\u001b[1;32m   1434\u001b[0m             \u001b[0mcheck_batch_axis\u001b[0m\u001b[0;34m=\u001b[0m\u001b[0;32mFalse\u001b[0m\u001b[0;34m,\u001b[0m\u001b[0;34m\u001b[0m\u001b[0m\n\u001b[0;32m-> 1435\u001b[0;31m             batch_size=batch_size)\n\u001b[0m\u001b[1;32m   1436\u001b[0m         \u001b[0;31m# Prepare validation data.\u001b[0m\u001b[0;34m\u001b[0m\u001b[0;34m\u001b[0m\u001b[0m\n\u001b[1;32m   1437\u001b[0m         \u001b[0;32mif\u001b[0m \u001b[0mvalidation_data\u001b[0m\u001b[0;34m:\u001b[0m\u001b[0;34m\u001b[0m\u001b[0m\n",
      "\u001b[0;32m~/anaconda3/envs/myDjangoEnv/lib/python3.6/site-packages/keras/engine/training.py\u001b[0m in \u001b[0;36m_standardize_user_data\u001b[0;34m(self, x, y, sample_weight, class_weight, check_batch_axis, batch_size)\u001b[0m\n\u001b[1;32m   1313\u001b[0m                                     \u001b[0moutput_shapes\u001b[0m\u001b[0;34m,\u001b[0m\u001b[0;34m\u001b[0m\u001b[0m\n\u001b[1;32m   1314\u001b[0m                                     \u001b[0mcheck_batch_axis\u001b[0m\u001b[0;34m=\u001b[0m\u001b[0;32mFalse\u001b[0m\u001b[0;34m,\u001b[0m\u001b[0;34m\u001b[0m\u001b[0m\n\u001b[0;32m-> 1315\u001b[0;31m                                     exception_prefix='target')\n\u001b[0m\u001b[1;32m   1316\u001b[0m         sample_weights = _standardize_sample_weights(sample_weight,\n\u001b[1;32m   1317\u001b[0m                                                      self._feed_output_names)\n",
      "\u001b[0;32m~/anaconda3/envs/myDjangoEnv/lib/python3.6/site-packages/keras/engine/training.py\u001b[0m in \u001b[0;36m_standardize_input_data\u001b[0;34m(data, names, shapes, check_batch_axis, exception_prefix)\u001b[0m\n\u001b[1;32m    137\u001b[0m                             \u001b[0;34m' to have shape '\u001b[0m \u001b[0;34m+\u001b[0m \u001b[0mstr\u001b[0m\u001b[0;34m(\u001b[0m\u001b[0mshapes\u001b[0m\u001b[0;34m[\u001b[0m\u001b[0mi\u001b[0m\u001b[0;34m]\u001b[0m\u001b[0;34m)\u001b[0m \u001b[0;34m+\u001b[0m\u001b[0;34m\u001b[0m\u001b[0m\n\u001b[1;32m    138\u001b[0m                             \u001b[0;34m' but got array with shape '\u001b[0m \u001b[0;34m+\u001b[0m\u001b[0;34m\u001b[0m\u001b[0m\n\u001b[0;32m--> 139\u001b[0;31m                             str(array.shape))\n\u001b[0m\u001b[1;32m    140\u001b[0m     \u001b[0;32mreturn\u001b[0m \u001b[0marrays\u001b[0m\u001b[0;34m\u001b[0m\u001b[0m\n\u001b[1;32m    141\u001b[0m \u001b[0;34m\u001b[0m\u001b[0m\n",
      "\u001b[0;31mValueError\u001b[0m: Error when checking target: expected dense_42 to have shape (None, 3) but got array with shape (112, 1)"
     ]
    }
   ],
   "source": [
    "classificador = Sequential()\n",
    "classificador.add(Dense(units = 4, activation = 'relu', input_dim = 4))\n",
    "classificador.add(Dense(units = 4, activation = 'relu'))\n",
    "classificador.add(Dense(units = 3, activation = 'softmax'))\n",
    "classificador.compile(optimizer = 'adam', loss = 'categorical_crossentropy',\n",
    "                      metrics = ['categorical_accuracy'])\n",
    "classificador.fit(previsores_treinamento, classe_treinamento, batch_size = 10,epochs = 1000)"
   ]
  },
  {
   "cell_type": "markdown",
   "metadata": {},
   "source": [
    "## O erro acontece porque não fizemos a transformação nos dados de saida"
   ]
  },
  {
   "cell_type": "code",
   "execution_count": null,
   "metadata": {
    "collapsed": true
   },
   "outputs": [],
   "source": []
  }
 ],
 "metadata": {
  "kernelspec": {
   "display_name": "myDjangoEnv",
   "language": "python",
   "name": "mydjangoenv"
  },
  "language_info": {
   "codemirror_mode": {
    "name": "ipython",
    "version": 3
   },
   "file_extension": ".py",
   "mimetype": "text/x-python",
   "name": "python",
   "nbconvert_exporter": "python",
   "pygments_lexer": "ipython3",
   "version": "3.6.2"
  }
 },
 "nbformat": 4,
 "nbformat_minor": 2
}
